<?xml version="1.0"?>
<robot name="robot">
  <!-- Base Link -->
  <link name="base_link">
    <visual>
      <geometry>
        <box size="0.2 0.3 0.1"/>
      </geometry>
      <origin xyz="0 0 0.05" rpy="0 0 0"/>
      <material name="blue">
        <color rgba="0 0 0.8 1"/>
      </material>
    </visual>
    <collision>
      <geometry>
        <box size="0.2 0.3 0.1"/>
      </geometry>
      <origin xyz="0 0 0.05" rpy="0 0 0"/>
    </collision>
    <inertial>
      <mass value="1.0"/>
      <inertia ixx="0.01" ixy="0.0" ixz="0.0" iyy="0.01" iyz="0.0" izz="0.01"/>
      <origin xyz="0 0 0.05" rpy="0 0 0"/>
    </inertial>
  </link>

  <!-- Left Wheel Link -->
  <link name="left_wheel">
    <visual>
      <geometry>
        <cylinder radius="0.033" length="0.02"/>
      </geometry>
      <origin xyz="0 0 0" rpy="1.5708 0 0"/>
      <material name="black">
        <color rgba="0.1 0.1 0.1 1"/>
      </material>
    </visual>
    <collision>
      <geometry>
        <cylinder radius="0.033" length="0.02"/>
      </geometry>
      <origin xyz="0 0 0" rpy="1.5708 0 0"/>
    </collision>
    <inertial>
      <mass value="0.1"/>
      <inertia ixx="0.00005" ixy="0.0" ixz="0.0" iyy="0.00005" iyz="0.0" izz="0.00005"/>
      <origin xyz="0 0 0" rpy="1.5708 0 0"/>
    </inertial>
  </link>

  <!-- Right Wheel Link -->
  <link name="right_wheel">
    <visual>
      <geometry>
        <cylinder radius="0.033" length="0.02"/>
      </geometry>
      <origin xyz="0 0 0" rpy="1.5708 0 0"/>
      <material name="black">
        <color rgba="0.1 0.1 0.1 1"/>
      </material>
    </visual>
    <collision>
      <geometry>
        <cylinder radius="0.033" length="0.02"/>
      </geometry>
      <origin xyz="0 0 0" rpy="1.5708 0 0"/>
    </collision>
    <inertial>
      <mass value="0.1"/>
      <inertia ixx="0.00005" ixy="0.0" ixz="0.0" iyy="0.00005" iyz="0.0" izz="0.00005"/>
      <origin xyz="0 0 0" rpy="1.5708 0 0"/>
    </inertial>
  </link>

  <!-- Caster Wheel Link -->
  <link name="caster_wheel">
    <visual>
      <geometry>
        <sphere radius="0.015"/>
      </geometry>
      <material name="grey">
        <color rgba="0.5 0.5 0.5 1"/>
      </material>
    </visual>
    <collision>
      <geometry>
        <sphere radius="0.015"/>
      </geometry>
    </collision>
    <inertial>
      <mass value="0.05"/>
      <inertia ixx="0.00001" ixy="0.0" ixz="0.0" iyy="0.00001" iyz="0.0" izz="0.00001"/>
    </inertial>
  </link>

  <!-- Left Wheel Joint -->
  <joint name="left_wheel_joint" type="continuous">
    <parent link="base_link"/>
    <child link="left_wheel"/>
    <origin xyz="0 0.085 0.033" rpy="0 0 0"/>
    <axis xyz="0 1 0"/>
  </joint>

  <!-- Right Wheel Joint -->
  <joint name="right_wheel_joint" type="continuous">
    <parent link="base_link"/>
    <child link="right_wheel"/>
    <origin xyz="0 -0.085 0.033" rpy="0 0 0"/>
    <axis xyz="0 1 0"/>
  </joint>

  <!-- Caster Joint -->
  <joint name="caster_joint" type="fixed">
    <parent link="base_link"/>
    <child link="caster_wheel"/>
    <origin xyz="0.07 0 0.015" rpy="0 0 0"/>
  </joint>

  <!-- ROS2 Control Tag -->
  <ros2_control name="tb6612fng_hardware" type="system">
    <hardware>
      <plugin>robot_control_py/TB6612FNGHardwareInterface</plugin>
      <param name="gpio_chip">gpiochip4</param>
      
      <!-- Left wheel motor pins -->
      <param name="left_in1_pin">8</param>
      <param name="left_in2_pin">7</param>
      <param name="left_pwm_pin">12</param>
      
      <!-- Right wheel motor pins -->
      <param name="right_in1_pin">23</param>
      <param name="right_in2_pin">24</param>
      <param name="right_pwm_pin">13</param>
      
      <!-- Standby pin (shared between motors) -->
      <param name="standby_pin">25</param>
      
      <!-- Motor configurations -->
      <param name="left_reversed">true</param>
      <param name="right_reversed">false</param>
      
      <!-- Maximum velocity that corresponds to 100% duty cycle -->
      <param name="max_velocity">10.0</param>
    </hardware>
    
    <!-- Left wheel -->
    <joint name="left_wheel_joint">
      <command_interface name="velocity"/>
      <state_interface name="position"/>
      <state_interface name="velocity"/>
    </joint>
    
    <!-- Right wheel -->
    <joint name="right_wheel_joint">
      <command_interface name="velocity"/>
      <state_interface name="position"/>
      <state_interface name="velocity"/>
    </joint>
  </ros2_control>
</robot> 